<?xml version='1.0' encoding='utf-8'?>
<robot name="300kg">
  <link name="world" />
  <joint name="joint_to_world" type="fixed">
    <parent link="world" />
    <child link="base" />
    <origin xyz="0 0 0" rpy="1.57 0 1.57" />
  </joint>
  <link name="base">
    <inertial>
      <origin xyz="-0.05 0 1.20E-01" rpy="0 0 0" />
      <mass value="216.24" />
      <inertia ixx="12.39" ixy="0.00E+00" ixz="0.00E+00" iyy="15.37" iyz="0.00E+00" izz="24.11" />
    </inertial>
    <visual>
      <origin xyz="0 0 0" rpy="0 0 0" />
      <geometry>
        <mesh filename="package://300kg/meshes/base.STL" />
      </geometry>
      <material>
        <color rgba="1 1 1 1" />
      </material>
    </visual>
    <collision>
      <origin xyz="0 0 0" rpy="0 0 0" />
      <geometry>
        <mesh filename="package://300kg/meshes/base.STL" />
      </geometry>
    </collision>
  </link>
  <link name="link1">
    <inertial>
      <origin xyz="0.00E+00 0.01 0.27" rpy="0 0 0" />
      <mass value="181.41" />
      <inertia ixx="4.66" ixy="0.00E+00" ixz="0.00E+00" iyy="17.51" iyz="0.00E+00" izz="17.11" />
    </inertial>
    <visual>
      <origin xyz="0 0 0" rpy="0 0 0" />
      <geometry>
        <mesh filename="package://300kg/meshes/link1.STL" />
      </geometry>
      <material>
        <color rgba="0 1 1 1" />
      </material>
    </visual>
    <collision>
      <origin xyz="0 0 0" rpy="0 0 0" />
      <geometry>
        <mesh filename="package://300kg/meshes/link1.STL" />
      </geometry>
    </collision>
  </link>
  <link name="link2">
    <inertial>
      <origin xyz="-0.02 -0.27 0.46" rpy="0 0 0" />
      <mass value="176.4" />
      <inertia ixx="39.01" ixy="0" ixz="0.00E+00" iyy="40.1" iyz="0.00E+00" izz="3.37" />
    </inertial>
    <visual>
      <origin xyz="0 0 0" rpy="0 0 0" />
      <geometry>
        <mesh filename="package://300kg/meshes/link2.STL" />
      </geometry>
      <material>
        <color rgba="1 0 1 1" />
      </material>
    </visual>
    <collision>
      <origin xyz="0 0 0" rpy="0 0 0" />
      <geometry>
        <mesh filename="package://300kg/meshes/link2.STL" />
      </geometry>
    </collision>
  </link>
  <link name="link3">
    <inertial>
      <origin xyz="0.13 0.09 0.13" rpy="0 0 0" />
      <mass value="102.61" />
      <inertia ixx="2.66" ixy="0" ixz="0.00E+00" iyy="3.4" iyz="0.00E+00" izz="2.32" />
    </inertial>
    <visual>
      <origin xyz="0.00E+00 0 0.00E+00" rpy="0 0.00E+00 0" />
      <geometry>
        <mesh filename="package://300kg/meshes/link3.STL" />
      </geometry>
      <material>
        <color rgba="1 1 0 1" />
      </material>
    </visual>
    <collision>
      <origin xyz="0 0 0" rpy="0 0 0" />
      <geometry>
        <mesh filename="package://300kg/meshes/link3.STL" />
      </geometry>
    </collision>
  </link>
  <link name="link4">
    <inertial>
      <origin xyz="0.45 -0.04 0" rpy="0 0 0" />
      <mass value="99.72" />
      <inertia ixx="1.84" ixy="0" ixz="0.00E+00" iyy="9.26" iyz="0.00E+00" izz="9.91" />
    </inertial>
    <visual>
      <origin xyz="0.00E+00 0 0.00E+00" rpy="0 0.00E+00 0" />
      <geometry>
        <mesh filename="package://300kg/meshes/link4.STL" />
      </geometry>
      <material>
        <color rgba="0 0 1 1" />
      </material>
    </visual>
    <collision>
      <origin xyz="0 0 0" rpy="0 0 0" />
      <geometry>
        <mesh filename="package://300kg/meshes/link4.STL" />
      </geometry>
    </collision>
  </link>
  <link name="link5">
    <inertial>
      <origin xyz="0.06 0.02 0" rpy="0 0 0" />
      <mass value="32.99" />
      <inertia ixx="0.33" ixy="0" ixz="0.00E+00" iyy="0.41" iyz="0.00E+00" izz="0.44" />
    </inertial>
    <visual>
      <origin xyz="0.00E+00 0 0.00E+00" rpy="0 0.00E+00 0" />
      <geometry>
        <mesh filename="package://300kg/meshes/link5.STL" />
      </geometry>
      <material>
        <color rgba="1 0 0 1" />
      </material>
    </visual>
    <collision>
      <origin xyz="0 0 0" rpy="0 0 0" />
      <geometry>
        <mesh filename="package://300kg/meshes/link5.STL" />
      </geometry>
    </collision>
  </link>
  <link name="link6">
    <inertial>
      <origin xyz="0.01 0 0" rpy="0 0 0" />
      <mass value="5.32" />
      <inertia ixx="0.03" ixy="0" ixz="0.00E+00" iyy="0.02" iyz="0.00E+00" izz="0.02" />
    </inertial>
    <visual>
      <origin xyz="0.00E+00 0 0.00E+00" rpy="0 0.00E+00 0" />
      <geometry>
        <mesh filename="package://300kg/meshes/link6.STL" />
      </geometry>
      <material>
        <color rgba="0 1 0 1" />
      </material>
    </visual>
    <collision>
      <origin xyz="0 0 0" rpy="0 0 0" />
      <geometry>
        <mesh filename="package://300kg/meshes/link6.STL" />
      </geometry>
    </collision>
  </link>
  <joint name="joint1" type="continuous">
    <parent link="base" />
    <child link="link1" />
    <origin xyz="0 0 0.2581" rpy="0 0 0" />
    <axis xyz="0 0 1" />
    <limit effort="10" velocity="1" />
  </joint>
  <joint name="joint2" type="continuous">
    <parent link="link1" />
    <child link="link2" />
    <origin xyz="0.33 0.022 0.3869" rpy="0 0 0" />
    <axis xyz="0 1 0" />
    <limit effort="10" velocity="1" />
  </joint>
  <joint name="joint3" type="continuous">
    <parent link="link2" />
    <child link="link3" />
    <origin xyz="0 -0.1605 1.15" rpy="0 0 0" />
    <axis xyz="0 1 0" />
    <limit effort="10" velocity="1" />
  </joint>
  <joint name="joint4" type="continuous">
    <parent link="link3" />
    <child link="link4" />
    <origin xyz="0.32 0.1385 0.23" rpy="0 0 0" />
    <axis xyz="1 0 0" />
    <limit effort="10" velocity="1" />
  </joint>
  <joint name="joint5" type="continuous">
    <parent link="link4" />
    <child link="link5" />
    <origin xyz="0.885 0 0" rpy="0 0 0" />
    <axis xyz="0 1 0" />
    <limit effort="10" velocity="1" />
  </joint>
  <joint name="joint6" type="continuous">
    <parent link="link5" />
    <child link="link6" />
    <origin xyz="0.2435 0 0" rpy="0 0 0" />
    <axis xyz="1 0 0" />
    <limit effort="10" velocity="1" />
  </joint>
</robot>